<?xml version="1.0"?>
<robot xmlns:xacro="http://www.ros.org/wiki/xacro"> 
 
  <xacro:property name="leg_joint_origin1" value="0 0.05 0"/>
  <xacro:property name="leg_joint_origin2" value="0 -0.05 0"/>
  <xacro:property name="leg_joint_origin3" value="0 0.05 0"/>
  <xacro:property name="leg_joint_origin4" value="0 -0.05 0"/>
  <xacro:property name="leg_joint_axis" value="0 0 1"/>
  
  <xacro:macro name="LF_leg_joint" params="name parent child">
    <joint name="${name}" type="revolute">
      <origin xyz="${leg_joint_origin1}" rpy="1.57 0 0"/>
      <parent link="${parent}"/>
      <child link="${child}"/>
      <axis xyz="${leg_joint_axis}"/>
      <limit lower="-1.5708" upper="1.5708" effort="30" velocity="1"/>
    </joint>
  </xacro:macro>
  
  <xacro:macro name="RF_leg_joint" params="name parent child">
    <joint name="${name}" type="revolute">
      <origin xyz="${leg_joint_origin2}" rpy="1.57 0 0"/>
      <parent link="${parent}"/>
      <child link="${child}"/>
      <axis xyz="${leg_joint_axis}"/>
      <limit lower="-1.5708" upper="1.5708" effort="30" velocity="1"/>
    </joint>
  </xacro:macro>
  
  <xacro:macro name="LR_leg_joint" params="name parent child">
    <joint name="${name}" type="revolute">
      <origin xyz="${leg_joint_origin3}" rpy="1.57 0 0"/>
      <parent link="${parent}"/>
      <child link="${child}"/>
      <axis xyz="${leg_joint_axis}"/>
      <limit lower="-1.5708" upper="1.5708" effort="30" velocity="1"/>
    </joint>
  </xacro:macro>
  
  <xacro:macro name="RR_leg_joint" params="name parent child">
    <joint name="${name}" type="revolute">
      <origin xyz="${leg_joint_origin4}" rpy="1.57 0 0"/>
      <parent link="${parent}"/>
      <child link="${child}"/>
      <axis xyz="${leg_joint_axis}"/>
      <limit lower="-1.5708" upper="1.5708" effort="30" velocity="1"/>
    </joint>
  </xacro:macro>
  
</robot>
